Workbook

Sheet Legende
B2: RALK – Preise, Pläne & Vertriebsmodell
B3: Stand Oktober 2026. Alle Preise in USD (Zielmarkt Afrika), netto, ohne Einrichtungsgebühr.
B5: So liest du die Datei
B6: Gelbe Zellen, blaue Schrift | C6: Eingaben/Annahmen – diese Zahlen darfst du ändern, alles andere rechnet sich neu.
B7: Schwarze Schrift | C7: Formeln – nicht überschreiben.
B8: Grüne Schrift | C8: Wert kommt aus einem anderen Blatt (meist „Preise & Pläne“).
B10: Blätter
B11: Preise & Pläne | C11: Preisstaffel, Mindestlizenz, Quellensteuer-Hinweis (DE/EN/FR), Preisrechner, Beispiele, Leistungsumfang.
B12: Mit Anwalts-Funnel | C12: 5-Jahres-Rechnung, wenn Kunden über Partner-Anwälte kommen (Provision 10 % / 5 %).
B13: Ohne Anwalt (Direkt) | C13: 5-Jahres-Rechnung, wenn du Kunden selbst gewinnst (Register-Ansprache, Anzeigen, Quick-Check) – ohne Provision, aber mit Werbekosten.
B14: Vergleich | C14: Beide Wege nebeneinander und kombiniert.
B15: Zielkunden – Register | C15: Öffentliche Seiten/Listen von Aufsichtsbehörden, Verbänden und Kammern, auf denen deine Zielkunden stehen – Grundlage für Kontaktlisten.
B17: Quellen
B18: Preise | C18: Neue Staffel (Okt. 2026, nach Marktvergleich): bis 1.000 MA 65 $, 1.001–10.000 MA 55 $, über 10.000 MA 45 $. Mindest-Jahreslizenz 5.000 $, keine Setup-Fee. Vorher (RALK_Preismodell): ≤4.000 65 $, 4.001–7.999 50 $, ≥8.000 45 $.
B19: Funnel-Zahlen | C19: Aus derselben Datei (Blätter „Anwalts-Funnel“, „Realistisch“, „Kosten & Marge“): 313 kontaktierte Kanzleien, 6 Bounces, 10 % Antwortquote, 30 % Konversion, 85 % Verlängerung, Provision 10 %/5 %, Fixkosten 5.640,12 €/Jahr.
B20: Korrekturen ggü. alter Datei | C20: 1) Antworten = Zugestellt × Antwortquote (alte Datei zeigte −1.878). 2) Einheitlich USD statt €/$ gemischt; € nur über den Wechselkurs. 3) Kein Ø-Preis von 35 € mehr – jeder Vertrag wird mit der echten Staffel gerechnet.
B21: Preisstaffel | C21: Der Satz gilt für alle Mitarbeitenden des Kunden. Übergangsregel: Wer in eine günstigere Klasse rutscht, zahlt nie weniger als die größte Organisation der Klasse darunter – kein Preissprung nach unten.
B22: Preispolitik | C22: Feste, veröffentlichte Preisliste wie bei Google Workspace, Microsoft 365, Atlassian und KnowBe4: gleicher Preis für alle, Mengenrabatt steckt in den Klassen, keine Einzelrabatte. Siehe Blatt „Marktvergleich“.
B27: Beispiel-Eingabe | C27: ← so sehen Eingabezellen aus

Sheet Marktvergleich
B2: Marktvergleich – wie andere Lizenzanbieter Preise machen
B3: Stand Oktober 2026, Listenpreise laut öffentlichen Quellen (Drittanbieter-Übersichten, nicht von den Herstellern bestätigt).
B5: Anbieter | C5: Preismodell | D5: Listenpreis pro Nutzer/Jahr | E5: Was RALK übernimmt
B6: Google Workspace | C6: Pläne nach Funktionsumfang, gleicher Preis pro Nutzer für alle; Jahresvertrag günstiger als monatlich; Enterprise auf Anfrage | D6: ca. 84–264 $ (7–22 $/Monat) | E6: Ein öffentlicher Preis für alle, keine Verhandlung
B7: Microsoft 365 | C7: Business-Pläne für kleinere Firmen, Enterprise-Pläne (E3/E5) für große; Preis pro Nutzer, Jahresbindung | D7: ca. 84–720 $ (7–60 $/Monat) | E7: Feste Preisliste; Preiserhöhungen mit Vorankündigung
B8: Atlassian (Jira) | C8: Jahresabos in festen Nutzerstufen; jede Nutzerzahl innerhalb einer Stufe zahlt gleich viel | D8: stufenabhängig | E8: Übergangsregel an den Klassengrenzen statt Preissprung
B9: KnowBe4 (Security-Awareness) | C9: Staffelpreis pro Platz nach Mengenband, günstiger bei längerer Laufzeit; ab 1.001 Plätzen Angebot | D9: ca. 20–45 $ (Liste, 3-Jahres-Vertrag) | E9: Mengenrabatt über Größenklassen
B10: AML-/Compliance-E-Learning (UK u. a.) | C10: Pro Kurs oder pro Nutzer, Mengenstaffel; große Anbieter (NAVEX, LRN, Thomson Reuters) nur auf Anfrage | D10: ca. 8–13 $ pro Kurs bzw. 60–200 $ pro Plattform-Nutzer | E10: RALK liegt mit 45–65 $ im Mittelfeld – für alle 13 Module
B11: Klassische Präsenzschulung (dein Modell) | C11: Einmalig pro Person | D11: ca. 462 $ für 5 Tage | E11: RALK: dauerhaft, nachweisbar, Bruchteil der Kosten
B13: Quellen
B14: https://www.cloudwards.net/google-workspace-plans-and-pricing/
B15: https://sanka.com/docs/migrate/tco/microsoft-365/
B16: https://community.atlassian.com/forums/discussion/3284604/jira-pricing-how-much-does-jira-cost-in-2026
B17: https://www.knowbe4.com/products/security-awareness-training-quote
B18: https://coggno.com/blog/compliance-training-pricing-2026/
B19: https://www.kyclookup.com/knowledgebase/best-aml-training-courses-uk/

Sheet Preise & Pläne
B2: Preise & Pläne – Jahreslizenz pro Mitarbeiter
B3: Fester Satz pro Mitarbeiter je Größenklasse (Mengenstaffel wie KnowBe4/Atlassian). Gilt für alle Mitarbeitenden des Kunden. Netto, USD, keine Einrichtungsgebühr, keine Einzelrabatte.
B5: Größenklasse | C5: bis Mitarbeiter | D5: USD / MA / Jahr | E5: in € | F5: Lizenz an der Obergrenze
B6: bis 1.000 | C6: 1000 | D6: 65 | E6: =D6*$C$12 | F6: =C6*D6
B7: 1.001 – 10.000 | C7: 10000 | D7: 55 | E7: =D7*$C$12 | F7: =C7*D7
B8: über 10.000 | C8: 999999999 | D8: 45 | E8: =D8*$C$12 | F8: –
B11: Mindest-Jahreslizenz (USD) | C11: 5000
B12: Wechselkurs USD → EUR | C12: 0.92
B13: Einrichtungsgebühr | C13: 0
B14: Vertragslaufzeit | C14: 12 Monate, verlängert sich automatisch
B15: Zahlung | C15: jährlich im Voraus, Rechnung + Überweisung, 14 Tage
B18: Hinweis Quellensteuer (steht auf ralk.io, Bestellseite und in den Lizenzbedingungen)
B19: DE | C19: Alle Preise verstehen sich netto in USD. Fällt im Land des Auftraggebers Quellensteuer oder eine vergleichbare Abgabe an, ist der Auftraggeber dafür allein verantwortlich und trägt sie zusätzlich zum Preis, sodass RALK als Auftragnehmer den vollen in Rechnung gestellten Betrag erhält.
B20: EN | C20: All prices are net amounts in USD. Any withholding tax or similar levy in the customer's country is the sole responsibility of the customer and is borne in addition to the price, so that RALK as the contractor receives the full invoiced amount.
B21: FR | C21: Tous les prix s'entendent nets, en USD. Toute retenue à la source ou taxe similaire applicable dans le pays du client est à la charge exclusive du client et s'ajoute au prix, de sorte que RALK, en tant que prestataire, perçoive l'intégralité du montant facturé.
B23: Preisrechner
B24: Anzahl Mitarbeiter des Kunden | C24: 400
B25: Satz pro Mitarbeiter (USD) | C25: =IF(C24<=$C$6,$D$6,IF(C24<=$C$7,$D$7,$D$8))
B26: Listenpreis (MA × Satz) | C26: =C24*C25
B27: Jahreslizenz (mit Mindestlizenz & Übergangsregel) | C27: =MAX(C24*IF(C24<=$C$6,$D$6,IF(C24<=$C$7,$D$7,$D$8)),$C$11,IF(C24>$C$6,$C$6*$D$6,0),IF(C24>$C$7,$C$7*$D$7,0))
B28: Jahreslizenz in € | C28: =C27*$C$12
B29: Effektiver Preis pro Kopf (USD) | C29: =IF(C24>0,C27/C24,0)
B31: Beispiele (Mitarbeiter frei änderbar)
B32: Mitarbeiter | C32: Satz USD | D32: Jahreslizenz USD | E32: Jahreslizenz € | F32: USD pro Kopf | G32: Bemerkung
B33: 10 | C33: =IF(B33<=$C$6,$D$6,IF(B33<=$C$7,$D$7,$D$8)) | D33: =MAX(B33*IF(B33<=$C$6,$D$6,IF(B33<=$C$7,$D$7,$D$8)),$C$11,IF(B33>$C$6,$C$6*$D$6,0),IF(B33>$C$7,$C$7*$D$7,0)) | E33: =D33*$C$12 | F33: =IF(B33>0,D33/B33,0) | G33: Mindestlizenz greift
B34: 50 | C34: =IF(B34<=$C$6,$D$6,IF(B34<=$C$7,$D$7,$D$8)) | D34: =MAX(B34*IF(B34<=$C$6,$D$6,IF(B34<=$C$7,$D$7,$D$8)),$C$11,IF(B34>$C$6,$C$6*$D$6,0),IF(B34>$C$7,$C$7*$D$7,0)) | E34: =D34*$C$12 | F34: =IF(B34>0,D34/B34,0) | G34: Mindestlizenz greift
B35: 77 | C35: =IF(B35<=$C$6,$D$6,IF(B35<=$C$7,$D$7,$D$8)) | D35: =MAX(B35*IF(B35<=$C$6,$D$6,IF(B35<=$C$7,$D$7,$D$8)),$C$11,IF(B35>$C$6,$C$6*$D$6,0),IF(B35>$C$7,$C$7*$D$7,0)) | E35: =D35*$C$12 | F35: =IF(B35>0,D35/B35,0) | G35: ab hier über Mindestlizenz
B36: 100 | C36: =IF(B36<=$C$6,$D$6,IF(B36<=$C$7,$D$7,$D$8)) | D36: =MAX(B36*IF(B36<=$C$6,$D$6,IF(B36<=$C$7,$D$7,$D$8)),$C$11,IF(B36>$C$6,$C$6*$D$6,0),IF(B36>$C$7,$C$7*$D$7,0)) | E36: =D36*$C$12 | F36: =IF(B36>0,D36/B36,0)
B37: 400 | C37: =IF(B37<=$C$6,$D$6,IF(B37<=$C$7,$D$7,$D$8)) | D37: =MAX(B37*IF(B37<=$C$6,$D$6,IF(B37<=$C$7,$D$7,$D$8)),$C$11,IF(B37>$C$6,$C$6*$D$6,0),IF(B37>$C$7,$C$7*$D$7,0)) | E37: =D37*$C$12 | F37: =IF(B37>0,D37/B37,0) | G37: typischer Mittelkunde
B38: 1000 | C38: =IF(B38<=$C$6,$D$6,IF(B38<=$C$7,$D$7,$D$8)) | D38: =MAX(B38*IF(B38<=$C$6,$D$6,IF(B38<=$C$7,$D$7,$D$8)),$C$11,IF(B38>$C$6,$C$6*$D$6,0),IF(B38>$C$7,$C$7*$D$7,0)) | E38: =D38*$C$12 | F38: =IF(B38>0,D38/B38,0) | G38: Klassengrenze
B39: 1001 | C39: =IF(B39<=$C$6,$D$6,IF(B39<=$C$7,$D$7,$D$8)) | D39: =MAX(B39*IF(B39<=$C$6,$D$6,IF(B39<=$C$7,$D$7,$D$8)),$C$11,IF(B39>$C$6,$C$6*$D$6,0),IF(B39>$C$7,$C$7*$D$7,0)) | E39: =D39*$C$12 | F39: =IF(B39>0,D39/B39,0) | G39: Übergangsregel: wie 1.000 MA
B40: 1182 | C40: =IF(B40<=$C$6,$D$6,IF(B40<=$C$7,$D$7,$D$8)) | D40: =MAX(B40*IF(B40<=$C$6,$D$6,IF(B40<=$C$7,$D$7,$D$8)),$C$11,IF(B40>$C$6,$C$6*$D$6,0),IF(B40>$C$7,$C$7*$D$7,0)) | E40: =D40*$C$12 | F40: =IF(B40>0,D40/B40,0) | G40: ab hier normaler 55-$-Satz
B41: 3000 | C41: =IF(B41<=$C$6,$D$6,IF(B41<=$C$7,$D$7,$D$8)) | D41: =MAX(B41*IF(B41<=$C$6,$D$6,IF(B41<=$C$7,$D$7,$D$8)),$C$11,IF(B41>$C$6,$C$6*$D$6,0),IF(B41>$C$7,$C$7*$D$7,0)) | E41: =D41*$C$12 | F41: =IF(B41>0,D41/B41,0) | G41: z. B. große Bank
B42: 8000 | C42: =IF(B42<=$C$6,$D$6,IF(B42<=$C$7,$D$7,$D$8)) | D42: =MAX(B42*IF(B42<=$C$6,$D$6,IF(B42<=$C$7,$D$7,$D$8)),$C$11,IF(B42>$C$6,$C$6*$D$6,0),IF(B42>$C$7,$C$7*$D$7,0)) | E42: =D42*$C$12 | F42: =IF(B42>0,D42/B42,0) | G42: z. B. Kenya Revenue Authority
B43: 10000 | C43: =IF(B43<=$C$6,$D$6,IF(B43<=$C$7,$D$7,$D$8)) | D43: =MAX(B43*IF(B43<=$C$6,$D$6,IF(B43<=$C$7,$D$7,$D$8)),$C$11,IF(B43>$C$6,$C$6*$D$6,0),IF(B43>$C$7,$C$7*$D$7,0)) | E43: =D43*$C$12 | F43: =IF(B43>0,D43/B43,0) | G43: Klassengrenze
B44: 10001 | C44: =IF(B44<=$C$6,$D$6,IF(B44<=$C$7,$D$7,$D$8)) | D44: =MAX(B44*IF(B44<=$C$6,$D$6,IF(B44<=$C$7,$D$7,$D$8)),$C$11,IF(B44>$C$6,$C$6*$D$6,0),IF(B44>$C$7,$C$7*$D$7,0)) | E44: =D44*$C$12 | F44: =IF(B44>0,D44/B44,0) | G44: Übergangsregel: wie 10.000 MA
B45: 12223 | C45: =IF(B45<=$C$6,$D$6,IF(B45<=$C$7,$D$7,$D$8)) | D45: =MAX(B45*IF(B45<=$C$6,$D$6,IF(B45<=$C$7,$D$7,$D$8)),$C$11,IF(B45>$C$6,$C$6*$D$6,0),IF(B45>$C$7,$C$7*$D$7,0)) | E45: =D45*$C$12 | F45: =IF(B45>0,D45/B45,0) | G45: ab hier normaler 45-$-Satz
B46: 15000 | C46: =IF(B46<=$C$6,$D$6,IF(B46<=$C$7,$D$7,$D$8)) | D46: =MAX(B46*IF(B46<=$C$6,$D$6,IF(B46<=$C$7,$D$7,$D$8)),$C$11,IF(B46>$C$6,$C$6*$D$6,0),IF(B46>$C$7,$C$7*$D$7,0)) | E46: =D46*$C$12 | F46: =IF(B46>0,D46/B46,0) | G46: Verband
B47: 30000 | C47: =IF(B47<=$C$6,$D$6,IF(B47<=$C$7,$D$7,$D$8)) | D47: =MAX(B47*IF(B47<=$C$6,$D$6,IF(B47<=$C$7,$D$7,$D$8)),$C$11,IF(B47>$C$6,$C$6*$D$6,0),IF(B47>$C$7,$C$7*$D$7,0)) | E47: =D47*$C$12 | F47: =IF(B47>0,D47/B47,0) | G47: z. B. Law Society of Kenya
B49: Übergangsregel (wie bei Atlassian-Stufen): Wer in eine günstigere Klasse rutscht, zahlt nie weniger als die größte Organisation der Klasse darunter (Spalte „Lizenz an der Obergrenze“). Beispiel: 1.001–1.181 MA zahlen 65.000 $ wie 1.000 MA, danach gilt 55 $; 10.001–12.222 MA zahlen 550.000 $ wie 10.000 MA, danach 45 $. So gibt es keinen Preissprung nach unten.
...

Sheet Mit Anwalts-Funnel
B2: Mit Anwalts-Funnel – Kunden über Partner-Anwälte
B3: Partner-Anwälte empfehlen RALK an ihre Mandanten und erhalten Provision. Alle Beträge USD.
B5: FUNNEL
B6: Kontaktierte Kanzleien | C6: 313
B7: Bounces (unzustellbar) | C7: 6
B8: Zugestellt | C8: =C6-C7
B9: Antwortquote | C9: 0.1
B10: Antworten | C10: =C8*C9
B11: Konversion Antwort → aktiver Empfehler | C11: 0.3
B12: Aktive Empfehler (rechnerisch) | C12: =C10*C11
B13: Zusagen bisher (zur Kontrolle) | C13: 18
B15: ANNAHMEN KUNDEN
B16: Neukunden je aktivem Empfehler pro Jahr | C16: 1
B17: Ø Mitarbeiter pro Kunde | C17: 400
B18: Jahreslizenz pro Kunde (USD) | C18: =MAX(C17*IF(C17<='Preise & Pläne'!$C$6,'Preise & Pläne'!$D$6,IF(C17<='Preise & Pläne'!$C$7,'Preise & Pläne'!$D$7,'Preise & Pläne'!$D$8)),'Preise & Pläne'!$C$11,IF(C17>'Preise & Pläne'!$C$6,'Preise & Pläne'!$C$6*'Preise & Pläne'!$D$6,0),IF(C17>'Preise & Pläne'!$C$7,'Preise & Pläne'!$C$7*'Preise & Pläne'!$D$7,0))
B19: Verlängerungsquote | C19: 0.85
B20: Provision 1. Jahr | C20: 0.1
B21: Provision Folgejahre | C21: 0.05
B22: Variable Kosten pro Nutzer/Jahr (USD) | C22: 1.5
B23: Fixkosten pro Jahr (USD) | C23: 6130
B25: 5-JAHRES-RECHNUNG | C25: Jahr 1 | D25: Jahr 2 | E25: Jahr 3 | F25: Jahr 4 | G25: Jahr 5
B26: Neukunden | C26: =$C$12*$C$16 | D26: =$C$12*$C$16 | E26: =$C$12*$C$16 | F26: =$C$12*$C$16 | G26: =$C$12*$C$16
B27: Aktive Kunden (inkl. Verlängerung) | C27: =C26+C28 | D27: =D26+D28 | E27: =E26+E28 | F27: =F26+F28 | G27: =G26+G28
B28: davon Bestandskunden (verlängert) | C28: =0 | D28: =C27*$C$19 | E28: =D27*$C$19 | F28: =E27*$C$19 | G28: =F27*$C$19
B29: Nutzer gesamt | C29: =C27*$C$17 | D29: =D27*$C$17 | E29: =E27*$C$17 | F29: =F27*$C$17 | G29: =G27*$C$17
B30: Umsatz Neukunden | C30: =C26*$C$18 | D30: =D26*$C$18 | E30: =E26*$C$18 | F30: =F26*$C$18 | G30: =G26*$C$18
B31: Umsatz Bestandskunden | C31: =C28*$C$18 | D31: =D28*$C$18 | E31: =E28*$C$18 | F31: =F28*$C$18 | G31: =G28*$C$18
B32: UMSATZ GESAMT | C32: =C30+C31 | D32: =D30+D31 | E32: =E30+E31 | F32: =F30+F31 | G32: =G30+G31
B33: − Provision Anwälte | C33: =-(C30*$C$20+C31*$C$21) | D33: =-(D30*$C$20+D31*$C$21) | E33: =-(E30*$C$20+E31*$C$21) | F33: =-(F30*$C$20+F31*$C$21) | G33: =-(G30*$C$20+G31*$C$21)
B34: − Variable Kosten | C34: =-C29*$C$22 | D34: =-D29*$C$22 | E34: =-E29*$C$22 | F34: =-F29*$C$22 | G34: =-G29*$C$22
B35: − Fixkosten | C35: =-$C$23 | D35: =-$C$23 | E35: =-$C$23 | F35: =-$C$23 | G35: =-$C$23
B36: GEWINN vor Steuer | C36: =SUM(C32:C35) | D36: =SUM(D32:D35) | E36: =SUM(E32:E35) | F36: =SUM(F32:F35) | G36: =SUM(G32:G35)
B37: Marge | C37: =IF(C32<>0,C36/C32,0) | D37: =IF(D32<>0,D36/D32,0) | E37: =IF(E32<>0,E36/E32,0) | F37: =IF(F32<>0,F36/F32,0) | G37: =IF(G32<>0,G36/G32,0)
B39: Summe 5 Jahre – Umsatz | C39: =SUM(C32:G32)
B40: Summe 5 Jahre – Provision | C40: =SUM(C33:G33)
B41: Summe 5 Jahre – Gewinn vor Steuer | C41: =SUM(C36:G36)
B43: Verlängerung als Erwartungswert (Anteil bleibt). Steuer nicht abgezogen (siehe Rechtsform-Blatt in deiner alten Datei). Großkunden/Verbände separat im Blatt „Vergleich“ ergänzbar.

Sheet Ohne Anwalt (Direkt)
B2: Ohne Anwalt – Kunden direkt gewinnen
B3: Du gewinnst Kunden selbst über Register-Ansprache, Anzeigen und den Quick-Check. Keine Provision, dafür Werbekosten. Alle Beträge USD.
B5: KANÄLE (pro Jahr, Jahr 1)
B6: Register-Ansprache: kontaktierte Institute | C6: 600
B7: Antwortquote | C7: 0.05
B8: Abschlussquote der Antworten | C8: 0.15
B9: → Neukunden aus Registern | C9: =C6*C7*C8
B10: Anzeigen (Google/Meta): Budget pro Jahr | C10: 6000
B11: Kosten pro Lead | C11: 40
B12: Abschlussquote Leads | C12: 0.05
B13: → Neukunden aus Anzeigen | C13: =IF(C11>0,C10/C11*C12,0)
B14: Quick-Check / organische Anfragen pro Jahr | C14: 60
B15: Abschlussquote | C15: 0.1
B16: → Neukunden organisch | C16: =C14*C15
B17: Neukunden Jahr 1 gesamt | C17: =C9+C13+C16
B18: Wachstum der Neukunden pro Jahr | C18: 0.2
B20: ANNAHMEN KUNDEN
B21: Ø Mitarbeiter pro Kunde | C21: 150
B22: Jahreslizenz pro Kunde (USD) | C22: =MAX(C21*IF(C21<='Preise & Pläne'!$C$6,'Preise & Pläne'!$D$6,IF(C21<='Preise & Pläne'!$C$7,'Preise & Pläne'!$D$7,'Preise & Pläne'!$D$8)),'Preise & Pläne'!$C$11,IF(C21>'Preise & Pläne'!$C$6,'Preise & Pläne'!$C$6*'Preise & Pläne'!$D$6,0),IF(C21>'Preise & Pläne'!$C$7,'Preise & Pläne'!$C$7*'Preise & Pläne'!$D$7,0))
B23: Verlängerungsquote | C23: 0.85
B24: Variable Kosten pro Nutzer/Jahr (USD) | C24: 3
B25: Fixkosten pro Jahr (USD) | C25: 6130
B27: 5-JAHRES-RECHNUNG | C27: Jahr 1 | D27: Jahr 2 | E27: Jahr 3 | F27: Jahr 4 | G27: Jahr 5
B28: Neukunden | C28: =$C$17*(1+$C$18)^0 | D28: =$C$17*(1+$C$18)^1 | E28: =$C$17*(1+$C$18)^2 | F28: =$C$17*(1+$C$18)^3 | G28: =$C$17*(1+$C$18)^4
B29: Aktive Kunden (inkl. Verlängerung) | C29: =C28+C30 | D29: =D28+D30 | E29: =E28+E30 | F29: =F28+F30 | G29: =G28+G30
B30: davon Bestandskunden (verlängert) | C30: =0 | D30: =C29*$C$23 | E30: =D29*$C$23 | F30: =E29*$C$23 | G30: =F29*$C$23
B31: Nutzer gesamt | C31: =C29*$C$21 | D31: =D29*$C$21 | E31: =E29*$C$21 | F31: =F29*$C$21 | G31: =G29*$C$21
B32: UMSATZ GESAMT | C32: =C29*$C$22 | D32: =D29*$C$22 | E32: =E29*$C$22 | F32: =F29*$C$22 | G32: =G29*$C$22
B33: − Werbekosten | C33: =-$C$10 | D33: =-$C$10 | E33: =-$C$10 | F33: =-$C$10 | G33: =-$C$10
B34: − Variable Kosten | C34: =-C31*$C$24 | D34: =-D31*$C$24 | E34: =-E31*$C$24 | F34: =-F31*$C$24 | G34: =-G31*$C$24
B35: − Fixkosten | C35: =-$C$25 | D35: =-$C$25 | E35: =-$C$25 | F35: =-$C$25 | G35: =-$C$25
B36: GEWINN vor Steuer | C36: =SUM(C32:C35) | D36: =SUM(D32:D35) | E36: =SUM(E32:E35) | F36: =SUM(F32:F35) | G36: =SUM(G32:G35)
B37: Marge | C37: =IF(C32<>0,C36/C32,0) | D37: =IF(D32<>0,D36/D32,0) | E37: =IF(E32<>0,E36/E32,0) | F37: =IF(F32<>0,F36/F32,0) | G37: =IF(G32<>0,G36/G32,0)
B39: Summe 5 Jahre – Umsatz | C39: =SUM(C32:G32)
B40: Summe 5 Jahre – Werbekosten | C40: =SUM(C33:G33)
B41: Summe 5 Jahre – Gewinn vor Steuer | C41: =SUM(C36:G36)
B43: Alle Quoten sind Annahmen ohne echte Daten – nach den ersten 3 Monaten mit echten Zahlen ersetzen.

Sheet Vergleich
B2: Vergleich – mit Anwalt, ohne Anwalt, kombiniert
B3: Kombiniert = beide Wege gleichzeitig; Fixkosten fallen dann nur einmal an. Alle Beträge USD, vor Steuer.
B5: KENNZAHL | C5: Jahr 1 | D5: Jahr 2 | E5: Jahr 3 | F5: Jahr 4 | G5: Jahr 5 | H5: Summe 5 J.
B6: Umsatz – mit Anwälten | C6: ='Mit Anwalts-Funnel'!C32 | D6: ='Mit Anwalts-Funnel'!D32 | E6: ='Mit Anwalts-Funnel'!E32 | F6: ='Mit Anwalts-Funnel'!F32 | G6: ='Mit Anwalts-Funnel'!G32 | H6: =SUM(C6:G6)
B7: Umsatz – direkt | C7: ='Ohne Anwalt (Direkt)'!C32 | D7: ='Ohne Anwalt (Direkt)'!D32 | E7: ='Ohne Anwalt (Direkt)'!E32 | F7: ='Ohne Anwalt (Direkt)'!F32 | G7: ='Ohne Anwalt (Direkt)'!G32 | H7: =SUM(C7:G7)
B8: Umsatz – kombiniert | C8: =C6+C7 | D8: =D6+D7 | E8: =E6+E7 | F8: =F6+F7 | G8: =G6+G7 | H8: =SUM(C8:G8)
B9: Gewinn – mit Anwälten | C9: ='Mit Anwalts-Funnel'!C36 | D9: ='Mit Anwalts-Funnel'!D36 | E9: ='Mit Anwalts-Funnel'!E36 | F9: ='Mit Anwalts-Funnel'!F36 | G9: ='Mit Anwalts-Funnel'!G36 | H9: =SUM(C9:G9)
B10: Gewinn – direkt | C10: ='Ohne Anwalt (Direkt)'!C36 | D10: ='Ohne Anwalt (Direkt)'!D36 | E10: ='Ohne Anwalt (Direkt)'!E36 | F10: ='Ohne Anwalt (Direkt)'!F36 | G10: ='Ohne Anwalt (Direkt)'!G36 | H10: =SUM(C10:G10)
B11: Gewinn – kombiniert (Fixkosten nur einmal) | C11: =C9+C10+'Ohne Anwalt (Direkt)'!$C$25 | D11: =D9+D10+'Ohne Anwalt (Direkt)'!$C$25 | E11: =E9+E10+'Ohne Anwalt (Direkt)'!$C$25 | F11: =F9+F10+'Ohne Anwalt (Direkt)'!$C$25 | G11: =G9+G10+'Ohne Anwalt (Direkt)'!$C$25 | H11: =SUM(C11:G11)
B12: Aktive Kunden – mit Anwälten | C12: ='Mit Anwalts-Funnel'!C27 | D12: ='Mit Anwalts-Funnel'!D27 | E12: ='Mit Anwalts-Funnel'!E27 | F12: ='Mit Anwalts-Funnel'!F27 | G12: ='Mit Anwalts-Funnel'!G27 | H12: =G12
B13: Aktive Kunden – direkt | C13: ='Ohne Anwalt (Direkt)'!C29 | D13: ='Ohne Anwalt (Direkt)'!D29 | E13: ='Ohne Anwalt (Direkt)'!E29 | F13: ='Ohne Anwalt (Direkt)'!F29 | G13: ='Ohne Anwalt (Direkt)'!G29 | H13: =G13
B14: Kosten der Kundengewinnung – Provision | C14: =-'Mit Anwalts-Funnel'!C33 | D14: =-'Mit Anwalts-Funnel'!D33 | E14: =-'Mit Anwalts-Funnel'!E33 | F14: =-'Mit Anwalts-Funnel'!F33 | G14: =-'Mit Anwalts-Funnel'!G33 | H14: =SUM(C14:G14)
B15: Kosten der Kundengewinnung – Werbung | C15: =-'Ohne Anwalt (Direkt)'!C33 | D15: =-'Ohne Anwalt (Direkt)'!D33 | E15: =-'Ohne Anwalt (Direkt)'!E33 | F15: =-'Ohne Anwalt (Direkt)'!F33 | G15: =-'Ohne Anwalt (Direkt)'!G33 | H15: =SUM(C15:G15)
B17: Lies es so: Anwälte bringen größere Kunden und kosten Provision; der Direktweg kostet Werbebudget und Zeit. Beides zusammen ist am stärksten. Der größte Hebel bleiben Verbände/Behörden (z. B. Law Society of Kenya, 30.000 × 45 $) – die stehen als Einzelfälle in deiner alten Datei.

Sheet Zielkunden – Register
B2: Zielkunden – öffentliche Register & Verzeichnisse
B3: Offizielle Seiten, auf denen lizenzierte Institute, Mitglieder oder Behörden gelistet sind. Grundlage für Kontaktlisten (Register-Ansprache). „URL per Suche bestätigt = ja“ heißt: Link kam per Websuche von der offiziellen Domain, die Seite wurde aber nicht geöffnet. Vor dem Erstellen von Kontaktlisten jede Seite kurz öffnen – manche Listen sind veraltet.
B5: Land | C5: Region / Aufsicht | D5: Kategorie | E5: Herausgeber | F5: Seite / Dokument | G5: Link | H5: Format | I5: Was steht drauf | J5: Sprache | K5: URL per Suche bestätigt | L5: Hinweise
B6: Regional | C6: BCEAO | D6: Banks | E6: BCEAO | F6: Liste des établissements de crédit agréés dans l'UMOA au 31 décembre 2025 | G6: https://www.bceao.int/sites/default/files/2026-04/LISTE%20DES%20%C3%89TABLISSEMENTS%20DE%20CR%C3%89DIT%20AGR%C3%89%C3%89S%20DANS%20L'UMOA%20au%2031%20d%C3%A9cembre%202025.pdf | H6: PDF | I6: 161 credit institutions (136 banks + 25 financial institutions) by country with licence codes; CI 33, Senegal 33, Mali 17, Togo 17 | J6: FR | K6: ja | L6: Confirmed in search index on official domain (direct fetch blocked in sandbox). Published April 2026. No contact details.
B7: Regional | C7: BCEAO | D7: Banks | E7: BCEAO | F7: Annuaire des banques, établissements financiers à caractère bancaire et compagnies financières de l'UMOA 2024 (mars 2026) | G7: https://www.bceao.int/sites/default/files/2026-04/Annuaire-des-Banques-etablissements-financiers-a-caractere-bancaire-et-compagnies-financieres-de-l-UMOA-2024_mars_2026.pdf | H7: PDF | I7: Directory of all UMOA banks with addresses, phone, management, shareholders, branch counts | J7: FR | K7: ja | L7: Confirmed in search index on official domain (direct fetch blocked in sandbox). Best source for contact details/CEO names.
B8: Regional | C8: BCEAO | D8: Banks | E8: BCEAO | F8: Paysage bancaire de l'UMOA | G8: https://www.bceao.int/fr/content/paysage-bancaire | H8: HTML | I8: Country-by-country banking landscape | J8: FR | K8: ja | L8: Confirmed in search index on official domain (direct fetch blocked in sandbox).
B9: Regional | C9: BCEAO | D9: Banks | E9: Commission Bancaire de l'UMOA | F9: Établissements assujettis au contrôle de la Commission Bancaire de l'UMOA | G9: https://cb-umoa.org/en/institutions-regulated-wamu-banking-commission | H9: HTML | I9: Hub with per-country PDF lists (banks, FIs, EMEs, EPs) for all 8 UMOA states | J9: FR | K9: ja | L9: Confirmed in search index on official domain (direct fetch blocked in sandbox).
B10: Regional | C10: COBAC/BEAC | D10: Banks | E10: COBAC (Commission Bancaire de l'Afrique Centrale) | F10: COBAC - Assujettis (annuaire des établissements) | G10: http://www.sgcobac.org/jcms/ess_7505/en/organes-faitiers?opLetterSearch=true&directoryLetter=B&memberId=&directory_start=20&directory_pageSize=50 | H10: Search tool | I10: A-Z directory of supervised credit institutions in CEMAC (Cameroon, Gabon, Congo...) with per-bank pages | J10: FR | K10: ja | L10: Confirmed in search index on official domain (direct fetch blocked in sandbox). Last consolidated list seen is 30 Sept 2020; HTTP only.
B11: Regional | C11: COBAC/BEAC | D11: Banks | E11: BEAC | F11: Lexique des Banques de la CEMAC | G11: https://www.beac.int/supervision-bancaire/lexique-banques-de-cemac/ | H11: HTML | I11: Glossary/list of CEMAC banks by country | J11: FR | K11: ja | L11: Confirmed in search index on official domain (direct fetch blocked in sandbox).
B12: Regional | C12: BCEAO | D12: Capital markets | E12: AMF-UMOA (Autorité des Marchés Financiers de l'UMOA) | F12: Liste des intervenants agréés du Marché Financier Régional de l'UMOA | G12: https://www.amf-umoa.org/accueil/intervenant | H12: Search tool | I12: SGIs (~36 brokers), SGOs (asset managers), custodians, business introducers; filterable by type/country with status | J12: FR | K12: ja | L12: Confirmed in search index on official domain (direct fetch blocked in sandbox). 394 professional cards renewed for 2026.
B13: Regional | C13: COBAC/BEAC | D13: Capital markets | E13: COSUMAF | F13: Intermédiaires - COSUMAF | G13: https://cosumaf.org/liste-intermediaires?category=cif | H13: Search tool | I13: Licensed brokers (sociétés de bourse ~26), asset managers (~16), advisers, custodians in CEMAC; approval no. and managers | J13: FR | K13: ja | L13: Confirmed in search index on official domain (direct fetch blocked in sandbox). English: cosumaf.org/intermediaries-list
B14: Regional | C14: COBAC/BEAC | D14: Capital markets | E14: COSUMAF | F14: L'ESSENTIEL 2e semestre 2025 | G14: https://cosumaf.org/files/documents/01KQRSJ4VRDZJ12Q805HTX1QYE.pdf | H14: PDF | I14: List of approved market actors as at 31 Dec 2025 | J14: FR | K14: ja | L14: Confirmed in search index on official domain (direct fetch blocked in sandbox).
B15: Regional | C15: FATF | D15: FATF/regional | E15: Financial Action Task Force | F15: Jurisdictions under Increased Monitoring - 19 June 2026 | G15: https://www.fatf-gafi.org/en/publications/High-risk-and-other-monitored-jurisdictions/increased-monitoring-june-2026.html | H15: HTML | I15: Grey list (22 jurisdictions) incl. Cameroon, Côte d'Ivoire, DR Congo, Kenya; DRC & CI judged to have substantially completed action plans (on-site visit due) | J15: EN | K15: ja | L15: Confirmed in search index on official domain (direct fetch blocked in sandbox). October 2026 plenary update may supersede; also see black-and-grey-lists hub.
B16: Regional | C16: FATF | D16: FATF/regional | E16: Financial Action Task Force | F16: "Black and grey" lists (hub) | G16: https://www.fatf-gafi.org/en/countries/black-and-grey-lists.html | H16: HTML | I16: Hub page always linking to the current grey and black lists | J16: EN | K16: ja | L16: Confirmed in search index on official domain (direct fetch blocked in sandbox).
... B33: DR Congo | C33: GABAC | D33: Banks | E33: Banque Centrale du Congo (BCC) | F33: Stabilité financière - Intermédiaires financiers (hub) | G33: https://www.bcc.cd/intermediaires-financiers | H33: HTML | I33: Hub of BCC registers: banks, microfinance, COOPEC, e-money, messageries financières, bureaux de change, ancillary PSPs | J33: FR | K33: ja | L33: Confirmed in search index on official domain (direct fetch blocked in sandbox).
B34: DR Congo | C34: GABAC | D34: FIU | E34: CENAREF (Cellule Nationale des Renseignements Financiers) | F34: CENAREF - no official website located | H34: HTML | I34: FIU (joined Egmont July 2026); regulations via Loi 22/068 AML/CFT | J34: FR | K34: nein | L34: No official domain found in search; contact via Ministry of Finance. Not invented.
B35: DR Congo | C35: GABAC | D35: Forex/Money transfer | E35: Banque Centrale du Congo (BCC) | F35: Messageries financières agréées | G35: https://www.bcc.cd/intermediaires-financiers/messageries-financieres | H35: HTML | I35: Licensed money-transfer operators (messageries financières) | J35: FR | K35: ja | L35: Confirmed in search index on official domain (direct fetch blocked in sandbox). Bureaux de change register is a sub-section of the same hub.
B36: DR Congo | C36: GABAC | D36: Industry association | E36: Association Congolaise des Banques (ACB) | F36: ACB - site officiel | G36: https://www.acb-rdc.cd | H36: HTML | I36: Mandatory association of all DRC credit institutions (membership compulsory by law) | J36: FR | K36: nein | L36: Domain cited in ACB LinkedIn announcement; not confirmed by search index.
B37: DR Congo | C37: GABAC | D37: Insurance | E37: ARCA (Autorité de Régulation et de Contrôle des Assurances) | F37: Sociétés d'assurances - Arca | G37: https://arca.cd/societes-dassurances-2/ | H37: HTML | I37: Licensed life & non-life insurers with approval numbers (Rawsur, Activa, SFA, SUNU, Mayfair, GPA, SONAS...) | J37: FR | K37: ja | L37: Confirmed in search index on official domain (direct fetch blocked in sandbox). Page copyright 2022; may lag.
B38: DR Congo | C38: GABAC | D38: Insurance | E38: ARCA | F38: Intermédiaires d'assurances - Arca | G38: https://arca.cd/intermediaires/ | H38: HTML | I38: Licensed insurance brokers and general agents (~29) | J38: FR | K38: ja | L38: Confirmed in search index on official domain (direct fetch blocked in sandbox).
B39: DR Congo | C39: GABAC | D39: Microfinance | E39: Banque Centrale du Congo (BCC) | F39: Sociétés de microfinance agréées | G39: https://www.bcc.cd/intermediaires-financiers/microfinance | H39: HTML | I39: Licensed microfinance companies (FINCA, Baobab, LOLC, SMICO...) - sector 116 institutions end-2025 | J39: FR | K39: ja | L39: Confirmed in search index on official domain (direct fetch blocked in sandbox).
B40: DR Congo | C40: GABAC | D40: Microfinance | E40: Banque Centrale du Congo (BCC) | F40: Caisses d'épargne et de crédit agréées | G40: https://www.bcc.cd/intermediaires-financiers/caisse-epargne-credit | H40: HTML | I40: Licensed savings & credit cooperatives (COOPEC) | J40: FR | K40: ja | L40: Confirmed in search index on official domain (direct fetch blocked in sandbox).
B41: DR Congo | C41: GABAC | D41: Payments/E-money | E41: Banque Centrale du Congo (BCC) | F41: Etablissements émetteurs de monnaie électronique | G41: https://www.bcc.cd/surveillance-des-intermediaires-financiers/intermediaires-financiers-assujettis/etablissements-de-credit/societes-financieres/ee | H41: HTML | I41: 4 e-money issuers: Vodacash (M-Pesa), Airtel Money RDC, Orange Money RDC, Afrimobile Money | J41: FR | K41: ja | L41: Confirmed in search index on official domain (direct fetch blocked in sandbox). Licence dates 2012-2015; may be stale.
B42: DR Congo | C42: GABAC | D42: Payments/E-money | E42: Banque Centrale du Congo (BCC) | F42: Prestataires des services connexes agréés | G42: https://www.bcc.cd/intermediaires-financiers/prestataires-services-connexes | H42: HTML | I42: Licensed payment-related service providers/aggregators (Monetbil, PayWay Congo, Nomba...) | J42: FR | K42: ja | L42: Confirmed in search index on official domain (direct fetch blocked in sandbox). Updated 15 July 2026.
B43: DR Congo | C43: GABAC | D43: Professional body | E43: Ordre National des Experts-Comptables (ONEC RDC) | F43: Loi créant l'ONEC (JO 19.02.2015) | G43: https://www.leganet.cd/Legislation/JO/2015/Numeros/JOS.19.02.2015.pdf | H43: PDF | I43: Founding law; ~347 active chartered accountants and 90 firms (2023); no public member list found | J43: FR | K43: ja | L43: Confirmed in search index on official domain (direct fetch blocked in sandbox). Official ONEC website not found.
B44: Kenya | C44: ESAAMLG | D44: Banks | E44: Central Bank of Kenya | F44: Directory of Licenced Commercial Banks, Mortgage Finance Institutions and Authorised Non-Operating Bank Holding Companies | G44: https://www.centralbank.go.ke/wp-content/uploads/2026/07/Directory-of-Licenced-Commercial-Banks-Mortgage-Finance-Institutions-and-Authorised-Non-Operating-Bank-Holding-Companies.pdf | H44: PDF | I44: ~38 commercial banks + mortgage finance cos + NOHCs with address, phone, email, website, peer group, branches | J44: EN | K44: ja | L44: Confirmed in search index on official domain (direct fetch blocked in sandbox). July 2026 upload. Contact details YES.
B45: Kenya | C45: ESAAMLG | D45: Banks | E45: Central Bank of Kenya | F45: Bank Supervision (hub for all directories) | G45: https://www.centralbank.go.ke/bank-supervision/ | H45: HTML | I45: Links to directories of banks, MFBs, forex bureaus, MRPs, CRBs, representative offices | J45: EN | K45: ja | L45: Confirmed in search index on official domain (direct fetch blocked in sandbox).
B46: Kenya | C46: ESAAMLG | D46: Capital markets | E46: Capital Markets Authority | F46: List of licensees - Capital Markets Authority | G46: https://licensees.cma.or.ke/licenses/1/ | H46: Search tool | I46: Licensees by category: stockbrokers, investment banks, fund managers (~43+), forex brokers, exchanges, etc. | J46: EN | K46: ja | L46: Confirmed in search index on official domain (direct fetch blocked in sandbox).
... B83: Senegal | C83: BCEAO | D83: FIU | E83: CENTIF Sénégal | F83: Rapport d'activités 2025 | G83: https://www.centif.sn/asset/attachements/rapports/Rapport_activite_2025.pdf.pdf | H83: PDF | I83: STR statistics by sector (banks ~83%), obliged-entity scope after 2024 law | J83: FR | K83: ja | L83: Confirmed in search index on official domain (direct fetch blocked in sandbox).
B84: Senegal | C84: BCEAO | D84: Microfinance | E84: DRS-SFD (Ministère des Finances) | F84: DRS-SFD - no list URL located | H84: HTML | I84: ~297 licensed SFDs (Oct 2025) | J84: FR | K84: nein | L84: No public named list found; request from DRS-SFD.
B85: Senegal | C85: BCEAO | D85: Payments/E-money | E85: Commission Bancaire de l'UMOA | F85: Liste des EME SN 2025 | G85: https://cb-umoa.org/sites/default/files/Liste%20des%20EME%20SN_2025.pdf | H85: PDF | I85: E-money issuers: Orange Finances Mobiles SN, Mobile Cash (Free Money), Wave Digital Finance, QuickPay | J85: FR | K85: ja | L85: Confirmed in search index on official domain (direct fetch blocked in sandbox). 11 payment institutions in BCEAO EP list.
B86: Senegal | C86: BCEAO | D86: Professional body | E86: ONECCA Sénégal | F86: ONECCA - site officiel | G86: https://www.onecca.sn | H86: HTML | I86: Chartered accountants/auditors order (mandatory registration) | J86: FR | K86: nein | L86: Domain cited by secondary sources; not confirmed in index.
B87: Cameroon | C87: COBAC/BEAC | D87: Banks | E87: COBAC | F87: COBAC - SOCIETE GENERALE CAMEROUN (example per-institution page) | G87: http://www.sgcobac.org/jcms/ess_6899/en/societe-generale-cameroun | H87: HTML | I87: Per-bank page in COBAC directory (Cameroon ~17-19 banks) | J87: FR | K87: ja | L87: Confirmed in search index on official domain (direct fetch blocked in sandbox).
B88: Cameroon | C88: COBAC/BEAC | D88: FIU | E88: ANIF Cameroun | F88: ANIF Cameroun - no official website located | H88: HTML | I88: FIU (Décret 2005/187); reporting entities per CEMAC Reg. 01/CEMAC/UMAC/CM | J88: FR | K88: nein | L88: No official domain found; do not guess.
B89: Cameroon | C89: COBAC/BEAC | D89: Industry association | E89: APECCAM | F89: L'APECCAM au fil des ans | G89: https://www.osidimbea.cm/associations/patrons/apeccam-fil/ | H89: HTML | I89: Bankers' association profile (27 member banks & FIs) | J89: FR | K89: nein | L89: Third-party page; official site not found.
B90: Cameroon | C90: COBAC/BEAC | D90: Microfinance | E90: MINFI Cameroun | F90: Liste des Établissements de Microfinance Agréés au 31 décembre 2021 | G90: https://minfi.gov.cm/liste-des-etablissements-de-microfinance-agrees-au-31-decembre-2021/ | H90: HTML | I90: EMFs by category & region with approval ref; 2026 list (385 EMFs, as at 31 Dec 2025) published by MINFI per press | J90: FR | K90: ja | L90: Confirmed in search index on official domain (direct fetch blocked in sandbox). Look for 2025 version on same site.
B91: Cameroon | C91: COBAC/BEAC | D91: Professional body | E91: Barreau du Cameroun | F91: Ordre des Avocats au Barreau du Cameroun | G91: https://barreaucameroun.org/fr/ | H91: HTML | I91: Bar website (communiqués; tableau not found online) | J91: FR | K91: ja | L91: Domain confirmed via PDFs hosted on it.
B92: Cameroon | C92: COBAC/BEAC | D92: Professional body | E92: ONECCA Cameroun | F92: ONECCA - site officiel | G92: https://www.onecca.cm | H92: HTML | I92: Chartered accountants order (~240 members 2017) | J92: FR | K92: nein | L92: Domain cited by secondary source.
B93: Ghana | C93: GIABA | D93: Banks | E93: Bank of Ghana | F93: Banks | G93: https://www.bog.gov.gh/supervision-regulation/registered-institutions/banks/ | H93: HTML | I93: ~23 universal banks with address, phone, website, email | J93: EN | K93: ja | L93: Confirmed in search index on official domain (direct fetch blocked in sandbox). Contact details YES.
B94: Ghana | C94: GIABA | D94: Banks | E94: Bank of Ghana | F94: All Institutions | G94: https://www.bog.gov.gh/supervision-regulation/all-institutions/ | H94: HTML | I94: Hub: banks, savings & loans, rural/community banks, deposit-taking MFIs, forex bureaux | J94: EN | K94: ja | L94: Confirmed in search index on official domain (direct fetch blocked in sandbox).
...
